<!DOCTYPE html>
<html lang="en">

<head>
    <meta charset="UTF-8">
    <meta name="viewport" content="width=device-width, initial-scale=1.0">
    <meta http-equiv="X-UA-Compatible" content="ie=edge">
    <title>Promise</title>
</head>

<body style=" width: 50%; margin: 0 auto;">
    <h1>Promise</h1>
    <p>Promise是一种封装和组合未来值的易于复用的机制。</p>
    <pre>
        var p = new Promise( function(X,Y){ //X Y 为两个回调
        // X()用于完成
        // Y()用于拒绝
        } );
    </pre>
    <ol>
        <li>一旦promise决议，它就成了不变的值</li>
        <li>反控制反转——把控制返还给调用代码，这也 是我们最开始想要的效果。
        </li>
        <li>一个很重要的好处是，可以把这个事件侦听对象提供给代码中多个独立的部分</li>
        <li>该对象就是分离的关注点之间一个中立的第三方协商机制。</li>
        <li>Promise决议（resolve, reject两个决议函数）可以只作为一种流程控制信号</li>
        <li>Promise 这种模式通过可信任的语义把回调作为参数传递</li>
        <li>我们把控制权放在了一个可信任的系统（Promise）中，
                这种系统的设计目的就是为了使异步编码更清晰</li>
        <li><hr><h4>链式流</h4></li>
        <li>每次你对 Promise 调用 then(..) ，它都会创建并返回一个新的 Promise</li>
        <li>不管从 then(..) 调用的完成回调（第一个参数）返回的值是什么，它都会被自动设置
                为被链接 Promise（第一点中的）的完成
        <pre>
        var p = Promise.resolve( 21 );
        var p2 = p.then( function(v){
        console.log( v ); // 21
        // 用值42填充p2
        return v * 2;
        } );
        // 连接p2
        p2.then( function(v){
        console.log( v ); // 42
        } );  
        </pre>   
        <h4>plus:</h4>
        <pre>
            让我们来简单总结一下使链式流程控制可行的 Promise 固有特性。
            • 调用 Promise 的 then(..) 会自动创建一个新的 Promise 从调用返回。
            • 在完成或拒绝处理函数内部，如果返回一个值或抛出一个异常，新返回的（可链接的）
            Promise 就相应地决议。
            • 如果完成或拒绝处理函数返回一个 Promise，它将会被展开，这样一来，不管它的决议
            值是什么，都会成为当前 then(..) 返回的链接 Promise 的决议值。
        </pre> 
        </li>
        <li>
                对这个 API 方法来说， Promise.resolve(..) 是一个精确的好名字，因为它实际上的结
                果可能是完成或拒绝(如果then展开的结果是拒绝的话)
        <pre>
        var rejectedTh = {
        then: function(resolved,rejected) {
        rejected( "Oops" );
        }
        };
        var rejectedPr = Promise.resolve( rejectedTh );
        </pre>
        </li>
        <li> reject(..) 不 会 像 resolve(..) 一 样 进 行 展 开。 如 果 向
                reject(..) 传入一个 Promise/thenable 值，它会把这个值原封不动地设置为
                拒绝理由。后续的拒绝处理函数接收到的是你实际传给 reject(..) 的那个
                Promise/thenable，而不是其底层的立即值</li>
        <li>try..catch 当然很好，但是无法跨异步操作工作。</li>
        <li>
        error-first 回调风格：
        <pre>
            function foo(cb) {
                setTimeout( function(){
                try {
                var x = baz.bar();
                cb( null, x ); // 成功！
                }
                catch (err) {
                cb( err );
                }
                }, 100 );
                }
                foo( function(err,val){
                if (err) {
                console.error( err ); // 烦 :(
                }
                else {
                console.log( val );
                }
            } );
        </pre>
        <p>严格说来，这一类错误处理是支持异步的，但完全无法很好地组合。多级 error-first 回调交织在一起，再加上这些无所不在的 if 检查语句，都不可避免地导致了回调地狱的风险</p>
        <hr>
        <pre>
            var p = Promise.reject( "Oops" );
            p.then(
            function fulfilled(){
            // 永远不会到达这里
            },
            function rejected(err){
            console.log( err ); // "Oops"
            }
            );
        </pre>
        </li>
        <li>
            <h4>编程思想：</h4>
            <p>开发者陷入“绝
                    Promise ｜ 209
                    望的陷阱”（pit of despair）（http://blog.codinghorror.com/falling-into-the-pit-of-success），要
                    为错误付出代价，只有更努力才能做对。他呼吁我们转而构建一个“成功的坑”（pit of
                    success），其中默认情况下你能够得到想要的结果（成功），想出错很难。</p>
        </li>
        <li>
            <h4>Promise 模式</h4>
            <p> Promise.all([ .. ])  数组中的值可以是 Promise、
                    thenable，甚至是立即值</p>
            
            <h4>Promise.race([ .. ])</h4>
            <p>只响应“第一个跨过终点线的 Promise”，而抛弃其他 Promise</p>
            <p>就像赛跑中有一个选手是从终点开始比赛一样！一旦有任何一个 Promise 决议为完成， Promise.race([ .. ]) 就会完成；一旦有任何一个 Promise 决议为拒绝，它就会拒绝。</p>
        </li>
        <li><h4>Promise API概述</h4>
    <pre>
        new Promise();  //构造器

        var p = new Promise(function(resolve,reject){
            // resolve(...);  用于决议/完成这个promise
            // reject(...);  用以拒绝和这个promise  
        });
    </pre>
    <hr>
    <pre>
        Promise.resolve() 和 Promise.reject(..)

        创建一个已被拒绝的Promise的会计方式是使用Promise.reject(..)
        下面两个promise是等价的
        var p1 = new Promise( function(resolve, reject){
            reject("Oops"); 
        });
        var p2 = Promise.reject("Oops");

        ---------------------------------------------------------

        Promise.resolve()常用于创建一个已完成的Promise, 使用方式与Promise.reject(...)类似;
        但是Promise.resolve()也会展开thenable值，再这种情况下，返回的Promise采用传入的这个thenable的最终决议值，可能是完成，也可能是拒绝

        var fulfilledTh = {
            then: function(cb) { cb( 42 ); }
            };
            var rejectedTh = {
            then: function(cb,errCb) {
            errCb( "Oops" );
            }
            };
            var p1 = Promise.resolve( fulfilledTh );
            var p2 = Promise.resolve( rejectedTh );
            // p1是完成的promise
            // p2是拒绝的promise

    </pre>
    <hr>
    <pre>
        then() 和 catch() 

        then(..) 接受一个或两个参数：第一个用于完成回调，第二个用于拒绝回调
        p.then( fulfilled );
        p.then( fulfilled, rejected );
        p.catch( rejected ); // 或者p.then( null, rejected )
    </pre>
    <hr>
    <pre>
        Promise.all([]) 和 Promise.race([])

        var p1 = Promise.resolve( 42 );
        var p2 = Promise.resolve( "Hello World" );
        var p3 = Promise.reject( "Oops" );
        Promise.race( [p1,p2,p3] )
        .then( function(msg){
        console.log( msg ); // 42
        } );
        Promise.all( [p1,p2,p3] )
        .catch( function(err){
        console.error( err ); // "Oops"
        } );
        Promise.all( [p1,p2] )
        .then( function(msgs){
        console.log( msgs ); // [42,"Hello World"]
        } );

        注意：当心！若向 Promise.all([ .. ]) 传入空数组，它会立即完成，但 Promise.race([ .. ]) 会挂住，且永远不会决议。
    </pre>
    

        </li>
        <li><h4>Promise 局限性</h4>
            <p> Promise 链中的错误很容易被无意中默默忽略掉</p>
        <pre>
        var p = foo( 42 )
        .then( STEP2 )
        .then( STEP3 );
        </pre>
        p指向then(STEP3)的Promise
        </li>
    </ol>
</body>
<script>
    // "C" 无法打断或抢占 "B" ，这是因为 Promise 的运作方式。
    // p.then(function () {
    //     p.then(function () {
    //         console.log("C");
    //     });
    //     console.log("A");
    // });
    // p.then(function () {
    //     console.log("B");
    // });
    //// A B C

    //吞掉错误或异常
    // var p = new Promise(function (resolve, reject) {
    //     foo.bar(); // foo未定义，所以会出错！
    //     resolve(42); // 永远不会到达这里 :(
    // });
    // p.then(
    //     function fulfilled() {
    //         console.log("ok");
    //         // 永远不会到达这里 :(
    //     },
    //     function rejected(err) {
    //         console.log(err);
    //         // err将会是一个TypeError异常对象来自foo.bar()这一行
    //     }
    // );
    // var p = {
    //     then: function (cb, errcb) {
    //         cb(42);
    //         errcb("evil laugh");
    //     }
    // };
    // p
    //     .then(
    //         function fulfilled(val) {
    //             console.log(val); // 42
    //         },
    //         function rejected(err) {
    //             // 啊，不应该运行！
    //             console.log(err); // 邪恶的笑
    //         }
    //     );


    // Promise.resolve(..)
    // 不要只是这么做：
    // foo(42)
    //     .then(function (v) {
    //         console.log(v);
    //     });
    // // 而要这么做：
    // Promise.resolve(foo(42))
    //     .then(function (v) {
    //         console.log(v);
    //     });

</script>

</html>